Workbook

Sheet 0. Introduction
A1: Self Assessment Questionnaire
A2: Introduction
B4: 📝 Instructions This self-assessment tool is designed to help Research Infrastructures (RIs) evaluate their environmental sustainability practices across multiple operational and strategic dimensions. It supports alignment with key EU regulations, standards, and the GreenDIGIT project methodology. The questionnaire is structured around the following thematic areas: • Governance and Compliance • Stakeholder Engagement and Awareness • Energy Efficiency and Decarbonisation • Environmental Monitoring and Impact • Pollution, Waste, and Circularity • Water and Ecosystems • Lifecycle Integration Each thematic area contains specific evaluation items, which the RI is asked to rate using a 3-level capability maturity scale. The responses generate insights into current performance, areas for improvement, and action priorities. ✅ How to use the tool 1. Start with the “Scope & Goals” tab Define the scope of the assessment and set target capability levels for each sub-topic. 2. Proceed to the “Assessment & Actions” tab For each question: • Select your current capability level (1–3). • Provide a brief rationale and attach any relevant evidence. • Review the automatically generated improvement priority and recommended action. 3. View results in the “Priority & Capability Results” tab This section compares your current levels against targets and flags whether goals are met. 4. Open the “Action Plan & Monitoring” tab • Review all recommended actions generated based on your assessment. • For each action, indicate the estimated effort required. • The sheet will automatically compute an Implementation Priority to help plan follow-up activities. 📌 Use this tool to: • Identify sustainability gaps and maturity levels • Support lifecycle-based environmental planning • Prepare for alignment with frameworks like CSRD, ESRS, EED, ISO 14001, and ESFRI • Feed directly into the development of sustainability strategies and environmental impact actions

Sheet 1. Scope & Goals
A1: Self Assessment Questionnaire
A2: Scope & Goals
B4: The sections below allow you to set scope and goals for your assessment. If you set neither the scope or goals (leave settings as they are), you will be presented with all requirements and results. We recommend that you begin with all topics and results unless you have guidance and support in setting and appropriate scope and fitting goals.
B7: Scope and Goals | C7: In Scope? | D7: Target Capability level?
B8: Governance and Compliance | F8: The table to the left allow you to set scope and targets for environmental sustainability capabilities of your RI.
B9: G1: Alignment with relevant EU regulations (CSRD, ESRS, EED, ESPR, WEEE, LCA, ISO14040, ISO14044) | C9: Yes | D9: Select....
B10: G2: Existence of a formal environmental sustainability strategy | C10: Yes | D10: Select....
B11: G3: Defined roles and responsibilities for sustainability | C11: Yes | D11: Select....
B12: G4: Inclusion of sustainability in internal policies or quality systems | C12: Yes | D12: Select....
B13: G5: Inclusion of sustainability in procurement or supplier management | C13: Yes | D13: Select....
B14: Stakeholder Engagement and Awareness
B15: S1: Sustainability awareness/training for staff | C15: Yes | D15: Select....
B16: S2: Involvement of stakeholders in environmental planning | C16: Yes | D16: Select....
B17: S3: Transparent communication of environmental performance | C17: Yes | D17: Select....
B18: Energy Efficiency and Decarbonisation
B19: E1: Adoption of renewable energy sources | C19: Yes | D19: Select....
B20: E2: AI-driven workload or energy optimisation | C20: Yes | D20: Select....
B21: E3: Waste heat recovery or reuse strategies | C21: Yes | D21: Select....
B22: E4: Power Usage Effectiveness (PUE) tracking and optimisation | C22: Yes | D22: Select....
B23: E5: Carbon Use Effectiveness (CUE) tracking and reduction | C23: Yes | D23: Select.... | F23: Capability levels are as follows:
B24: E6: Flexible energy usage or smart grid responsiveness | C24: Yes | D24: Select....
B25: Environmental Monitoring and Impact | F25: Level 1: Initial / Ad hoc | G25: Awareness is minimal, and practices are largely unstructured
B26: M1: Measurement of environmental KPIs (GHG, energy, water, waste) | C26: Yes | D26: Select....
B27: M2: Use of environmental metrics in planning and reporting | C27: Yes | D27: Select.... | F27: Level 2: Developing / Partial | G27: Some measures exist, but they are inconsistent or not formalised.
B28: M3: Lifecycle-based environmental impact assessment (based on LCA methodology) | C28: Yes | D28: Select....
B29: M4: Use of WUE (Water Usage Effectiveness) or similar water metrics | C29: Yes | D29: Select.... | F29: Level 3: Established / Assured | G29: The RI is confident that the topic is systematically addressed with well-defined practices.
B30: M5: Implementation of monitoring tools/platforms | C30: Yes | D30: Select....
B31: Pollution, Waste, and Circularity
B32: P1: Reduction of operational waste (incl. e-waste) | C32: Yes | D32: Select....
B33: P2: End-of-life management for equipment | C33: Yes | D33: Select....
B34: P3: Circular IT practices (reuse, remanufacturing, modularity) | C34: Yes | D34: Select....
B35: P4: Pollution control (air, water, soil) | C35: Yes | D35: Select....
B36: P5: Use of low-impact or non-toxic materials | C36: Yes | D36: Select....
B37: Water and Ecosystems
B38: W1: Water usage monitoring and reduction strategies | C38: Yes | D38: Select....
B39: W2: Impact on local ecosystems or biodiversity | C39: Yes | D39: Select....
B40: W3: Rainwater harvesting, reuse, or runoff management | C40: Yes | D40: Select....
B41: W4: Water-based cooling systems and water efficiency strategies | C41: Yes | D41: Select....
B42: Lifecycle Integration
B43: L1: Sustainability embedded in the design phase | C43: Yes | D43: Select....
...

Sheet 2-3. Assessment & Actions
A1: Self Assessment Questionnaire
A2: Assessment
B3: Topic area | C3: Type of requirement | D3: Requirement code | E3: Question | F3: Lifecycle Phase | G3: Environmental Dimension | H3: Associated Metric | I3: Reference (Standard/Policy) | J3: Impact Magnitude | K3: Impact Likelihood | L3: Improvement Priority | M3: Capability Level | N3: Descriptions | O3: Recommended Action | P3: Self assessment score | Q3: Rationale for score | R3: Evidence Type Expected | S3: Evidence (e.g. available documents / records / URLs)
B5: ='1. Scope & Goals'!B8 -> Governance and Compliance
B6: ='1. Scope & Goals'!B9 -> G1: Alignment with relevant EU regulations (CSRD, ESRS, EED, ESPR, WEEE, LCA, ISO14040, ISO14044) | C6: Output / Achievement | D6: G1.1 | E6: To what extent is the RI aligned with relevant EU environmental regulations such as CSRD, ESRS, EED, ESPR, WEEE, LCA, ISO14040, ISO14044? | F6: Cross-cutting | G6: Non-environmental | H6: N/A | I6: CSRD, ESRS E1-E5, ESPR, EED, WEEE, LCA, ISO14040, ISO14044 | J6: High | K6: High | L6: =IF(OR(J6="High", K6="High"), IF(AND(J6="High", K6="High"), "High", IF(OR(J6="High", K6="Medium", J6="Medium", K6="High"), "High", "Medium")), IF(AND(J6="Medium", K6="Medium"), "Medium", "Low")) -> High | M6: 1 | N6: The RI is not actively considering EU environmental regulations or is unaware of specific obligations. | O6: Conduct a regulatory gap analysis to identify which EU environmental regulations apply and where the RI is currently non-compliant. Engage legal or compliance expertise to support interpretation if needed. | P6: Select.... | R6: Compliance documentation / Legal review
J7: Medium | K7: Medium | L7: =IF(OR(J7="High", K7="High"), IF(AND(J7="High", K7="High"), "High", IF(OR(J7="High", K7="Medium", J7="Medium", K7="High"), "High", "Medium")), IF(AND(J7="Medium", K7="Medium"), "Medium", "Low")) -> Medium | M7: 2 | N7: The RI is aware of applicable regulations and has initiated some exploratory or preparatory activities, but there is no structured compliance plan. | O7: Update internal documentation and procedures to close identified regulatory gaps. Begin implementing key compliance actions with clear timelines and responsibilities.
J8: Low | K8: Low | L8: =IF(OR(J8="High", K8="High"), IF(AND(J8="High", K8="High"), "High", IF(OR(J8="High", K8="Medium", J8="Medium", K8="High"), "High", "Medium")), IF(AND(J8="Medium", K8="Medium"), "Medium", "Low")) -> Low | M8: 3 | N8: The RI has mapped relevant regulations, assigned responsibilities, and embedded compliance requirements into formal policies and operational procedures. | O8: No further action required. Maintain alignment by reviewing regulatory changes annually and updating internal policies accordingly.
C9: Task / activity | D9: G1.2 | E9: Has the RI conducted a review or gap analysis to identify which regulations apply and how they are addressed? | F9: Cross-cutting | G9: Non-environmental | H9: N/A | I9: CSRD, ESRS E1-E5, ESPR, WEEE | J9: High | K9: High | L9: =IF(OR(J9="High", K9="High"), IF(AND(J9="High", K9="High"), "High", IF(OR(J9="High", K9="Medium", J9="Medium", K9="High"), "High", "Medium")), IF(AND(J9="Medium", K9="Medium"), "Medium", "Low")) -> High | M9: 1 | N9: No structured review or gap analysis has been conducted; awareness of obligations is minimal or outdated. | O9: Initiate a structured regulatory review to identify applicable EU regulations (e.g. CSRD, ESRS, EED, ESPR, WEEE). Engage relevant internal or external expertise and document initial findings. | P9: Select.... | R9: Gap analysis / Internal review documentation
J10: Medium | K10: Medium | L10: =IF(OR(J10="High", K10="High"), IF(AND(J10="High", K10="High"), "High", IF(OR(J10="High", K10="Medium", J10="Medium", K10="High"), "High", "Medium")), IF(AND(J10="Medium", K10="Medium"), "Medium", "Low")) -> Medium | M10: 2 | N10: A basic review has been done; some gaps identified, but follow-up actions are limited or informal. | O10: Expand and update the regulatory gap analysis. Clarify which obligations are partially addressed, and prepare an action plan to resolve any gaps identified.
J11: Low | K11: Low | L11: =IF(OR(J11="High", K11="High"), IF(AND(J11="High", K11="High"), "High", IF(OR(J11="High", K11="Medium", J11="Medium", K11="High"), "High", "Medium")), IF(AND(J11="Medium", K11="Medium"), "Medium", "Low")) -> Low | M11: 3 | N11: A comprehensive, up-to-date gap analysis is in place; regularly reviewed and informs compliance actions. | O11: No action needed. Maintain and periodically update the gap analysis in line with evolving legislation and internal priorities.
B12: ='1. Scope & Goals'!B10 -> G2: Existence of a formal environmental sustainability strategy | C12: Output / Achievement | D12: G2.1 | E12: Is there a documented environmental sustainability strategy in place, endorsed by leadership and periodically updated? | F12: Cross-cutting | G12: Non-environmental | H12: N/A | I12: ESRS E1, ISO 14001 | J12: Medium | K12: High | L12: =IF(OR(J12="High", K12="High"), IF(AND(J12="High", K12="High"), "High", IF(OR(J12="High", K12="Medium", J12="Medium", K12="High"), "High", "Medium")), IF(AND(J12="Medium", K12="Medium"), "Medium", "Low")) -> High | M12: 1 | N12: No environmental sustainability strategy exists, or it is informal and not institutionally endorsed. | O12: Draft a documented environmental sustainability strategy that outlines goals, scope, and key priorities. Secure leadership engagement to initiate endorsement. | P12: Select.... | R12: Strategy document / Policy endorsement
J13: Medium | K13: Medium | L13: =IF(OR(J13="High", K13="High"), IF(AND(J13="High", K13="High"), "High", IF(OR(J13="High", K13="Medium", J13="Medium", K13="High"), "High", "Medium")), IF(AND(J13="Medium", K13="Medium"), "Medium", "Low")) -> Medium | M13: 2 | N13: A strategy exists and covers key areas, but it is not comprehensive or regularly reviewed. | O13: Formalise leadership endorsement of the strategy and ensure it includes a mechanism for periodic updates. Begin integrating it into RI-level decision-making.
J14: Low | K14: Low | L14: =IF(OR(J14="High", K14="High"), IF(AND(J14="High", K14="High"), "High", IF(OR(J14="High", K14="Medium", J14="Medium", K14="High"), "High", "Medium")), IF(AND(J14="Medium", K14="Medium"), "Medium", "Low")) -> Low | M14: 3 | N14: A formal strategy is in place, endorsed by leadership, reviewed regularly, and linked to operational planning. | O14: No action needed. Maintain periodic reviews and ensure the strategy remains aligned with evolving sustainability goals and regulations.
B15: ='1. Scope & Goals'!B11 -> G3: Defined roles and responsibilities for sustainability | C15: Task / activity | D15: G3.1 | E15: Are roles and responsibilities for environmental sustainability clearly assigned across relevant functions within the RI? | F15: Cross-cutting | G15: Non-environmental | H15: N/A | I15: ISO 14001, CSRD | J15: Medium | K15: High | L15: =IF(OR(J15="High", K15="High"), IF(AND(J15="High", K15="High"), "High", IF(OR(J15="High", K15="Medium", J15="Medium", K15="High"), "High", "Medium")), IF(AND(J15="Medium", K15="Medium"), "Medium", "Low")) -> High | M15: 1 | N15: No roles or responsibilities are defined for sustainability-related actions. | O15: Identify key functions and assign clear responsibilities for environmental sustainability. Ensure responsibility is not siloed but shared across operational and strategic roles. | P15: Select.... | R15: Organisational documentation
J16: Medium | K16: Medium | L16: =IF(OR(J16="High", K16="High"), IF(AND(J16="High", K16="High"), "High", IF(OR(J16="High", K16="Medium", J16="Medium", K16="High"), "High", "Medium")), IF(AND(J16="Medium", K16="Medium"), "Medium", "Low")) -> Medium | M16: 2 | N16: Some roles are assigned, but responsibilities are not clearly documented or consistently applied. | O16: Document the assigned responsibilities formally (e.g. in organisational charts, role descriptions, quality systems) and ensure they are communicated internally.
J17: Low | K17: Low | L17: =IF(OR(J17="High", K17="High"), IF(AND(J17="High", K17="High"), "High", IF(OR(J17="High", K17="Medium", J17="Medium", K17="High"), "High", "Medium")), IF(AND(J17="Medium", K17="Medium"), "Medium", "Low")) -> Low | M17: 3 | N17: Roles and responsibilities are formally assigned, documented, and integrated into operational procedures. | O17: No action needed. Sustain clarity and alignment of responsibilities, and update assignments when organisational roles or sustainability goals evolve.
B18: ='1. Scope & Goals'!B12 -> G4: Inclusion of sustainability in internal policies or quality systems | C18: Task / activity | D18: G4.1 | E18: To what extent is environmental sustainability integrated into the RI’s internal policies, management systems, or quality frameworks? | F18: Cross-cutting | G18: Non-environmental | H18: N/A | I18: ISO 14001, CSRD, EMAS | J18: Medium | K18: High | L18: =IF(OR(J18="High", K18="High"), IF(AND(J18="High", K18="High"), "High", IF(OR(J18="High", K18="Medium", J18="Medium", K18="High"), "High", "Medium")), IF(AND(J18="Medium", K18="Medium"), "Medium", "Low")) -> High | M18: 1 | N18: Environmental considerations are not referenced in internal policies or management systems. | O18: Review existing policies, management systems, and quality frameworks to identify where environmental sustainability is absent. Begin drafting updates or addenda that reflect sustainability considerations. | P18: Select.... | R18: Policy / Management system records
J19: Medium | K19: Medium | L19: =IF(OR(J19="High", K19="High"), IF(AND(J19="High", K19="High"), "High", IF(OR(J19="High", K19="Medium", J19="Medium", K19="High"), "High", "Medium")), IF(AND(J19="Medium", K19="Medium"), "Medium", "Low")) -> Medium | M19: 2 | N19: Sustainability is mentioned in some policies or quality processes, but integration is limited or inconsistent. | O19: Expand integration of sustainability elements across internal systems. Ensure alignment with recognised frameworks such as ISO 14001 or ISO 9001 (with sustainability add-ons), and involve relevant departments in updates.
J20: Low | K20: Low | L20: =IF(OR(J20="High", K20="High"), IF(AND(J20="High", K20="High"), "High", IF(OR(J20="High", K20="Medium", J20="Medium", K20="High"), "High", "Medium")), IF(AND(J20="Medium", K20="Medium"), "Medium", "Low")) -> Low | M20: 3 | N20: Environmental sustainability is systematically integrated across internal policies, quality management, and procedures. | O20: No action needed. Continue internal reviews to maintain full integration and alignment with emerging sustainability standards.
B21: ='1. Scope & Goals'!B13 -> G5: Inclusion of sustainability in procurement or supplier management | C21: Task / activity | D21: G5.1 | E21: Does the RI include environmental sustainability criteria in procurement processes and supplier evaluations? | F21: Cross-cutting | G21: Non-environmental | H21: % of suppliers evaluated with environmental criteria (optional) | I21: ISO 20400, ESRS G1, ESRS E5, EU Green Public Procurement Guidelines | J21: Medium | K21: High | L21: =IF(OR(J21="High", K21="High"), IF(AND(J21="High", K21="High"), "High", IF(OR(J21="High", K21="Medium", J21="Medium", K21="High"), "High", "Medium")), IF(AND(J21="Medium", K21="Medium"), "Medium", "Low")) -> High | M21: 1 | N21: Environmental criteria are not considered in procurement or supplier evaluation. | O21: Begin integrating basic environmental sustainability criteria into procurement guidelines and supplier selection processes. Reference relevant standards (e.g. EU Green Public Procurement) where applicable. | P21: Select.... | R21: Procurement documents / Supplier criteria
J22: Medium | K22: Medium | L22: =IF(OR(J22="High", K22="High"), IF(AND(J22="High", K22="High"), "High", IF(OR(J22="High", K22="Medium", J22="Medium", K22="High"), "High", "Medium")), IF(AND(J22="Medium", K22="Medium"), "Medium", "Low")) -> Medium | M22: 2 | N22: Some environmental criteria are used, but not systematically or across all procurement categories. | O22: Expand and formalise sustainability criteria in procurement documents and supplier contracts. Ensure criteria are measurable and consistently applied across purchases.
J23: Low | K23: Low | L23: =IF(OR(J23="High", K23="High"), IF(AND(J23="High", K23="High"), "High", IF(OR(J23="High", K23="Medium", J23="Medium", K23="High"), "High", "Medium")), IF(AND(J23="Medium", K23="Medium"), "Medium", "Low")) -> Low | M23: 3 | N23: Environmental sustainability is consistently integrated into procurement processes and supplier assessments. | O23: No action needed. Maintain criteria updates and consider supplier engagement strategies to support continuous sustainability improvement.
B24: ='1. Scope & Goals'!B14 -> Stakeholder Engagement and Awareness
B25: ='1. Scope & Goals'!B15 -> S1: Sustainability awareness/training for staff | C25: Task / activity | D25: S1.1 | E25: To what extent does the RI provide staff training or awareness programmes on environmental sustainability topics relevant to their roles? | F25: Cross-cutting | G25: Non-environmental | H25: % of staff trained annually, number of training sessions | I25: ISO 14001, ESRS | J25: Medium | K25: High | L25: =IF(OR(J25="", K25=""), "", IF(OR(J25="High", K25="High"), IF(AND(J25="High", K25="High"), "High", IF(OR(J25="High", K25="Medium", J25="Medium", K25="High"), "High", "Medium")), IF(AND(J25="Medium", K25="Medium"), "Medium", "Low"))) -> High | M25: 1 | N25: No sustainability training or awareness activities are in place. | O25: Develop and deliver basic sustainability awareness sessions for staff. Tailor content to general operational relevance and RI objectives. | P25: Select.... | R25: Training records, attendance logs, course materials
J26: Medium | K26: Medium | L26: =IF(OR(J26="", K26=""), "", IF(OR(J26="High", K26="High"), IF(AND(J26="High", K26="High"), "High", IF(OR(J26="High", K26="Medium", J26="Medium", K26="High"), "High", "Medium")), IF(AND(J26="Medium", K26="Medium"), "Medium", "Low"))) -> Medium | M26: 2 | N26: Some ad hoc or optional training is available, but not systematic. | O26: Establish structured training programmes with role-specific content. Include periodic refreshers and track staff participation and feedback.
J27: Low | K27: Low | L27: =IF(OR(J27="", K27=""), "", IF(OR(J27="High", K27="High"), IF(AND(J27="High", K27="High"), "High", IF(OR(J27="High", K27="Medium", J27="Medium", K27="High"), "High", "Medium")), IF(AND(J27="Medium", K27="Medium"), "Medium", "Low"))) -> Low | M27: 3 | N27: Structured, role-specific sustainability training is delivered regularly and tracked. | O27: No action needed. Maintain comprehensive training programmes and consider integrating sustainability awareness into onboarding and performance reviews.
B28: ='1. Scope & Goals'!B16 -> S2: Involvement of stakeholders in environmental planning | C28: Task / activity | D28: S2.1 | E28: Are relevant stakeholders (e.g. users, suppliers, partners) engaged in environmental planning or sustainability goal-setting processes? | F28: Cross-cutting | G28: Non-environmental | H28: N/A | I28: ISO 14001, ESRS 1 | J28: Medium | K28: High | L28: =IF(OR(J28="", K28=""), "", IF(OR(J28="High", K28="High"), IF(AND(J28="High", K28="High"), "High", IF(OR(J28="High", K28="Medium", J28="Medium", K28="High"), "High", "Medium")), IF(AND(J28="Medium", K28="Medium"), "Medium", "Low"))) -> High | M28: 1 | N28: Stakeholders are not engaged in environmental planning or goal setting. | O28: Identify key stakeholder groups and initiate basic engagement on environmental topics (e.g. surveys, meetings, informal consultations). | P28: Select.... | R28: Meeting records, consultation summaries, stakeholder input reports
J29: Medium | K29: Medium | L29: =IF(OR(J29="", K29=""), "", IF(OR(J29="High", K29="High"), IF(AND(J29="High", K29="High"), "High", IF(OR(J29="High", K29="Medium", J29="Medium", K29="High"), "High", "Medium")), IF(AND(J29="Medium", K29="Medium"), "Medium", "Low"))) -> Medium | M29: 2 | N29: Stakeholder input is sought occasionally but not structured or consistently applied. | O29: Develop a structured stakeholder engagement plan that includes regular input into sustainability planning or goal-setting processes. Document outcomes and integrate feedback.
J30: Low | K30: Low | L30: =IF(OR(J30="", K30=""), "", IF(OR(J30="High", K30="High"), IF(AND(J30="High", K30="High"), "High", IF(OR(J30="High", K30="Medium", J30="Medium", K30="High"), "High", "Medium")), IF(AND(J30="Medium", K30="Medium"), "Medium", "Low"))) -> Low | M30: 3 | N30: Stakeholders are regularly and systematically involved in environmental planning processes. | O30: No action needed. Continue proactive stakeholder engagement and track participation and influence on environmental decisions.
B31: ='1. Scope & Goals'!B17 -> S3: Transparent communication of environmental performance | C31: Output / Achievement | D31: S3.1 | E31: Does the RI regularly communicate its environmental performance, actions, or goals to internal and external stakeholders? | F31: Cross-cutting | G31: Non-environmental | H31: Frequency and scope of communications (e.g., reports/year) | I31: CSRD, ESRS E1, ISO 14063 | J31: Medium | K31: High | L31: =IF(OR(J31="", K31=""), "", IF(OR(J31="High", K31="High"), IF(AND(J31="High", K31="High"), "High", IF(OR(J31="High", K31="Medium", J31="Medium", K31="High"), "High", "Medium")), IF(AND(J31="Medium", K31="Medium"), "Medium", "Low"))) -> High | M31: 1 | N31: Environmental performance is not communicated externally or internally. | O31: Identify key performance metrics and develop internal channels for sharing environmental information (e.g. newsletters, intranet updates). | P31: Select.... | R31: Sustainability reports, public disclosures, stakeholder briefings
J32: Medium | K32: Medium | L32: =IF(OR(J32="", K32=""), "", IF(OR(J32="High", K32="High"), IF(AND(J32="High", K32="High"), "High", IF(OR(J32="High", K32="Medium", J32="Medium", K32="High"), "High", "Medium")), IF(AND(J32="Medium", K32="Medium"), "Medium", "Low"))) -> Medium | M32: 2 | N32: Some communications occur, but are informal or irregular. | O32: Identify key performance metrics and develop internal channels for sharing environmental information (e.g. newsletters, intranet updates).
J33: Low | K33: Low | L33: =IF(OR(J33="", K33=""), "", IF(OR(J33="High", K33="High"), IF(AND(J33="High", K33="High"), "High", IF(OR(J33="High", K33="Medium", J33="Medium", K33="High"), "High", "Medium")), IF(AND(J33="Medium", K33="Medium"), "Medium", "Low"))) -> Low | M33: 3 | N33: Environmental performance is communicated regularly, transparently, and in structured formats. | O33: Establish regular reporting cycles and communication plans for both internal and external audiences. Include key performance indicators, progress on goals, and future plans.
B34: ='1. Scope & Goals'!B18 -> Energy Efficiency and Decarbonisation
B35: ='1. Scope & Goals'!B19 -> E1: Adoption of renewable energy sources | C35: Output / Achievement | D35: E1.1 | E35: What proportion of the RI’s energy consumption is sourced from renewable energy, and how is this verified? | F35: Operation | G35: Energy | H35: % of energy from renewable sources | I35: ISO 50001, ESRS E1, EU Renewable Energy Directive | J35: High | K35: High | L35: =IF(OR(J35="High", K35="High"), IF(AND(J35="High", K35="High"), "High", IF(OR(J35="High", K35="Medium", J35="Medium", K35="High"), "High", "Medium")), IF(AND(J35="Medium", K35="Medium"), "Medium", "Low")) -> High | M35: 1 | N35: The RI does not use or track renewable energy usage. | O35: Assess the current energy mix and identify opportunities to procure or transition to renewable energy sources. Start collecting data and documentation to verify sources (e.g. supplier declarations, energy certificates). | P35: Select.... | R35: Energy bills, supplier contracts, renewable energy certificates
J36: Medium | K36: Medium | L36: =IF(OR(J36="High", K36="High"), IF(AND(J36="High", K36="High"), "High", IF(OR(J36="High", K36="Medium", J36="Medium", K36="High"), "High", "Medium")), IF(AND(J36="Medium", K36="Medium"), "Medium", "Low")) -> Medium | M36: 2 | N36: Some energy comes from renewable sources, but tracking is limited or informal. | O36: Increase the share of renewable energy through updated contracts or on-site generation. Implement processes for regular verification and reporting (e.g. through Guarantees of Origin, utility audits).
J37: Low | K37: Low | L37: =IF(OR(J37="High", K37="High"), IF(AND(J37="High", K37="High"), "High", IF(OR(J37="High", K37="Medium", J37="Medium", K37="High"), "High", "Medium")), IF(AND(J37="Medium", K37="Medium"), "Medium", "Low")) -> Low | M37: 3 | N37: A high proportion of energy is sourced from renewables, verified through formal documentation or contracts. | O37: No action needed. Continue monitoring and ensure transparency in reporting renewable energy sourcing and verification.
B38: ='1. Scope & Goals'!B20 -> E2: AI-driven workload or energy optimisation | C38: Task / activity | D38: E2.1 | E38: Are AI or automation systems used to optimise energy consumption across compute, cooling, or other infrastructure components? | F38: Operation | G38: Energy | H38: Estimated energy savings (%) from AI/automation | I38: ISO 50001, EN 50600-4-8 (Energy Reuse) | J38: Medium | K38: High | L38: =IF(OR(J38="High", K38="High"), IF(AND(J38="High", K38="High"), "High", IF(OR(J38="High", K38="Medium", J38="Medium", K38="High"), "High", "Medium")), IF(AND(J38="Medium", K38="Medium"), "Medium", "Low")) -> High | M38: 1 | N38: No AI or automation tools are in place for energy optimisation. | O38: Identify infrastructure areas with high energy use and evaluate the potential of AI or automation tools for energy optimisation. Initiate pilot projects or feasibility assessments. | P38: Select.... | R38: System documentation, control software descriptions, performance reports
J39: Medium | K39: Medium | L39: =IF(OR(J39="High", K39="High"), IF(AND(J39="High", K39="High"), "High", IF(OR(J39="High", K39="Medium", J39="Medium", K39="High"), "High", "Medium")), IF(AND(J39="Medium", K39="Medium"), "Medium", "Low")) -> Medium | M39: 2 | N39: Some systems exist, but usage is limited to specific components or lacks ongoing refinement. | O39: Expand use of AI-driven or automated systems for energy optimisation in key areas (e.g. dynamic workload distribution, smart cooling). Document energy savings and lessons learned.
J40: Low | K40: Low | L40: =IF(OR(J40="High", K40="High"), IF(AND(J40="High", K40="High"), "High", IF(OR(J40="High", K40="Medium", J40="Medium", K40="High"), "High", "Medium")), IF(AND(J40="Medium", K40="Medium"), "Medium", "Low")) -> Low | M40: 3 | N40: Advanced AI/automation is used systematically across operations to monitor and optimise energy use. | O40: No action needed. Maintain optimisation systems and review performance periodically to identify further improvement opportunities.
B41: ='1. Scope & Goals'!B21 -> E3: Waste heat recovery or reuse strategies | C41: Task / activity | D41: E3.1 | E41: Does the RI implement strategies to recover or reuse waste heat generated by infrastructure? | F41: Operation | G41: Energy | H41: Energy reuse factor (ERF), % of recovered heat reused | I41: EN 50600-4-6, ISO 50001 | J41: Medium | K41: High | L41: =IF(OR(J41="High", K41="High"), IF(AND(J41="High", K41="High"), "High", IF(OR(J41="High", K41="Medium", J41="Medium", K41="High"), "High", "Medium")), IF(AND(J41="Medium", K41="Medium"), "Medium", "Low")) -> High | M41: 1 | N41: No waste heat recovery strategies are in place or considered. | O41: Assess the feasibility of heat recovery based on infrastructure type and thermal load. Identify potential use cases (e.g. heating buildings, district heating, internal reuse). | P41: Select.... | R41: Technical system designs, energy recovery logs, reuse feasibility studies
...

Sheet 4. Priority&Capability Results
A1: Self Assessment Questionnaire
A2: Capability Results
B4: Topic Area | C4: Scope and goals | E4: Questions | F4: Capability assessment | I4: Targets | J4: Improvement Priority
C5: In Scope | D5: Capability goal | E5: Question code | F5: Level 1 | G5: Level 2 | H5: Level 3
B6: =_xlfn.XLOOKUP(E6,'2-3. Assessment & Actions'!D:D,'2-3. Assessment & Actions'!B:B) -> G1: Alignment with relevant EU regulations (CSRD, ESRS, EED, ESPR, WEEE, LCA, ISO14040, ISO14044) | C6: =_xlfn.XLOOKUP(B6, '1. Scope & Goals'!B:B,'1. Scope & Goals'!C:C) -> Yes | D6: =_xlfn.LET(_xlpm.val,_xlfn.XLOOKUP(B6,'1. Scope & Goals'!B:B,'1. Scope & Goals'!D:D), IF(_xlpm.val="Select…. ","N/A",_xlpm.val)) -> N/A | E6: {=_xlfn.UNIQUE(_xlfn._xlws.FILTER('2-3. Assessment & Actions'!D6:D144, '2-3. Assessment & Actions'!D6:D144<>""))} -> G1.1 | F6: =IF(C6="No", "Not In Scope", IF('2-3. Assessment & Actions'!P6="Select…. ","Not Answered",IF('2-3. Assessment & Actions'!P6>=1,"Passed","Failed"))) -> Not Answered | G6: =IF(C6="No", "Not In Scope", IF('2-3. Assessment & Actions'!P6="Select…. ","Not Answered",IF('2-3. Assessment & Actions'!P6>=2,"Passed","Failed"))) -> Not Answered | H6: =IF(C6="No", "Not In Scope", IF('2-3. Assessment & Actions'!P6="Select…. ","Not Answered",IF('2-3. Assessment & Actions'!P6>=3,"Passed","Failed"))) -> Not Answered | I6: =IF(D6="N/A", "No target set", IF('2-3. Assessment & Actions'!P6="Select…. ", "No results given", IF('2-3. Assessment & Actions'!P6>=D6, "Targets met","Targets not met"))) -> No target set | J6: =IF(C6="No", "Not In Scope", IF('2-3. Assessment & Actions'!P6="Select…. ","Not Answered",IF('2-3. Assessment & Actions'!P6=1,'2-3. Assessment & Actions'!L6,(IF('2-3. Assessment & Actions'!P6=2,'2-3. Assessment & Actions'!L7,'2-3. Assessment & Actions'!L8))))) -> Not Answered
C7: =_xlfn.XLOOKUP(B6, '1. Scope & Goals'!B:B,'1. Scope & Goals'!C:C) -> Yes | D7: =_xlfn.LET(_xlpm.val,_xlfn.XLOOKUP(B6,'1. Scope & Goals'!B:B,'1. Scope & Goals'!D:D), IF(_xlpm.val="Select…. ","N/A",_xlpm.val)) -> N/A | E7: G1.2 | F7: =IF(C7="No", "Not In Scope", IF('2-3. Assessment & Actions'!P9="Select…. ","Not Answered",IF('2-3. Assessment & Actions'!P9>=1,"Passed","Failed"))) -> Not Answered | G7: =IF(C7="No", "Not In Scope", IF('2-3. Assessment & Actions'!P9="Select…. ","Not Answered",IF('2-3. Assessment & Actions'!P9>=2,"Passed","Failed"))) -> Not Answered | H7: =IF(C7="No", "Not In Scope", IF('2-3. Assessment & Actions'!P9="Select…. ","Not Answered",IF('2-3. Assessment & Actions'!P9>=3,"Passed","Failed"))) -> Not Answered | I7: =IF(D7="N/A", "No target set", IF('2-3. Assessment & Actions'!P9="Select…. ", "No results given", IF('2-3. Assessment & Actions'!P9>=D7, "Targets met","Targets not met"))) -> No target set | J7: =IF(C7="No", "Not In Scope", IF('2-3. Assessment & Actions'!P9="Select…. ","Not Answered",IF('2-3. Assessment & Actions'!P9=1,'2-3. Assessment & Actions'!L9,(IF('2-3. Assessment & Actions'!P9=2,'2-3. Assessment & Actions'!L10,'2-3. Assessment & Actions'!L11))))) -> Not Answered
B8: =_xlfn.XLOOKUP(E8,'2-3. Assessment & Actions'!D:D,'2-3. Assessment & Actions'!B:B) -> G2: Existence of a formal environmental sustainability strategy | C8: =_xlfn.XLOOKUP(B8, '1. Scope & Goals'!B:B,'1. Scope & Goals'!C:C) -> Yes | D8: =_xlfn.LET(_xlpm.val,_xlfn.XLOOKUP(B8,'1. Scope & Goals'!B:B,'1. Scope & Goals'!D:D), IF(_xlpm.val="Select…. ","N/A",_xlpm.val)) -> N/A | E8: G2.1 | F8: =IF(C8="No", "Not In Scope", IF('2-3. Assessment & Actions'!P12="Select…. ","Not Answered",IF('2-3. Assessment & Actions'!P12>=1,"Passed","Failed"))) -> Not Answered | G8: =IF(C8="No", "Not In Scope", IF('2-3. Assessment & Actions'!P12="Select…. ","Not Answered",IF('2-3. Assessment & Actions'!P12>=2,"Passed","Failed"))) -> Not Answered | H8: =IF(C8="No", "Not In Scope", IF('2-3. Assessment & Actions'!P12="Select…. ","Not Answered",IF('2-3. Assessment & Actions'!P12>=3,"Passed","Failed"))) -> Not Answered | I8: =IF(D8="N/A", "No target set", IF('2-3. Assessment & Actions'!P12="Select…. ", "No results given", IF('2-3. Assessment & Actions'!P12>=D8, "Targets met","Targets not met"))) -> No target set | J8: =IF(C8="No", "Not In Scope", IF('2-3. Assessment & Actions'!P12="Select…. ","Not Answered",IF('2-3. Assessment & Actions'!P12=1,'2-3. Assessment & Actions'!L12,(IF('2-3. Assessment & Actions'!P12=2,'2-3. Assessment & Actions'!L13,'2-3. Assessment & Actions'!L14))))) -> Not Answered
B9: =_xlfn.XLOOKUP(E9,'2-3. Assessment & Actions'!D:D,'2-3. Assessment & Actions'!B:B) -> G3: Defined roles and responsibilities for sustainability | C9: =_xlfn.XLOOKUP(B9, '1. Scope & Goals'!B:B,'1. Scope & Goals'!C:C) -> Yes | D9: =_xlfn.LET(_xlpm.val,_xlfn.XLOOKUP(B9,'1. Scope & Goals'!B:B,'1. Scope & Goals'!D:D), IF(_xlpm.val="Select…. ","N/A",_xlpm.val)) -> N/A | E9: G3.1 | F9: =IF(C9="No", "Not In Scope", IF('2-3. Assessment & Actions'!P15="Select…. ","Not Answered",IF('2-3. Assessment & Actions'!P15>=1,"Passed","Failed"))) -> Not Answered | G9: =IF(C9="No", "Not In Scope", IF('2-3. Assessment & Actions'!P15="Select…. ","Not Answered",IF('2-3. Assessment & Actions'!P15>=2,"Passed","Failed"))) -> Not Answered | H9: =IF(C9="No", "Not In Scope", IF('2-3. Assessment & Actions'!P15="Select…. ","Not Answered",IF('2-3. Assessment & Actions'!P15>=3,"Passed","Failed"))) -> Not Answered | I9: =IF(D9="N/A", "No target set", IF('2-3. Assessment & Actions'!P15="Select…. ", "No results given", IF('2-3. Assessment & Actions'!P15>=D9, "Targets met","Targets not met"))) -> No target set | J9: =IF(C9="No", "Not In Scope", IF('2-3. Assessment & Actions'!P15="Select…. ","Not Answered",IF('2-3. Assessment & Actions'!P15=1,'2-3. Assessment & Actions'!L15,(IF('2-3. Assessment & Actions'!P15=2,'2-3. Assessment & Actions'!L16,'2-3. Assessment & Actions'!L17))))) -> Not Answered
B10: =_xlfn.XLOOKUP(E10,'2-3. Assessment & Actions'!D:D,'2-3. Assessment & Actions'!B:B) -> G4: Inclusion of sustainability in internal policies or quality systems | C10: =_xlfn.XLOOKUP(B10, '1. Scope & Goals'!B:B,'1. Scope & Goals'!C:C) -> Yes | D10: =_xlfn.LET(_xlpm.val,_xlfn.XLOOKUP(B10,'1. Scope & Goals'!B:B,'1. Scope & Goals'!D:D), IF(_xlpm.val="Select…. ","N/A",_xlpm.val)) -> N/A | E10: G4.1 | F10: =IF(C10="No", "Not In Scope", IF('2-3. Assessment & Actions'!P18="Select…. ","Not Answered",IF('2-3. Assessment & Actions'!P18>=1,"Passed","Failed"))) -> Not Answered | G10: =IF(C10="No", "Not In Scope", IF('2-3. Assessment & Actions'!P18="Select…. ","Not Answered",IF('2-3. Assessment & Actions'!P18>=2,"Passed","Failed"))) -> Not Answered | H10: =IF(C10="No", "Not In Scope", IF('2-3. Assessment & Actions'!P18="Select…. ","Not Answered",IF('2-3. Assessment & Actions'!P18>=3,"Passed","Failed"))) -> Not Answered | I10: =IF(D10="N/A", "No target set", IF('2-3. Assessment & Actions'!P18="Select…. ", "No results given", IF('2-3. Assessment & Actions'!P18>=D10, "Targets met","Targets not met"))) -> No target set | J10: =IF(C10="No", "Not In Scope", IF('2-3. Assessment & Actions'!P18="Select…. ","Not Answered",IF('2-3. Assessment & Actions'!P18=1,'2-3. Assessment & Actions'!L18,(IF('2-3. Assessment & Actions'!P18=2,'2-3. Assessment & Actions'!L19,'2-3. Assessment & Actions'!L20))))) -> Not Answered
B11: =_xlfn.XLOOKUP(E11,'2-3. Assessment & Actions'!D:D,'2-3. Assessment & Actions'!B:B) -> G5: Inclusion of sustainability in procurement or supplier management | C11: =_xlfn.XLOOKUP(B11, '1. Scope & Goals'!B:B,'1. Scope & Goals'!C:C) -> Yes | D11: =_xlfn.LET(_xlpm.val,_xlfn.XLOOKUP(B11,'1. Scope & Goals'!B:B,'1. Scope & Goals'!D:D), IF(_xlpm.val="Select…. ","N/A",_xlpm.val)) -> N/A | E11: G5.1 | F11: =IF(C11="No", "Not In Scope", IF('2-3. Assessment & Actions'!P21="Select…. ","Not Answered",IF('2-3. Assessment & Actions'!P21>=1,"Passed","Failed"))) -> Not Answered | G11: =IF(C11="No", "Not In Scope", IF('2-3. Assessment & Actions'!P21="Select…. ","Not Answered",IF('2-3. Assessment & Actions'!P21>=2,"Passed","Failed"))) -> Not Answered | H11: =IF(C11="No", "Not In Scope", IF('2-3. Assessment & Actions'!P21="Select…. ","Not Answered",IF('2-3. Assessment & Actions'!P21>=3,"Passed","Failed"))) -> Not Answered | I11: =IF(D11="N/A", "No target set", IF('2-3. Assessment & Actions'!P21="Select…. ", "No results given", IF('2-3. Assessment & Actions'!P21>=D11, "Targets met","Targets not met"))) -> No target set | J11: =IF(C11="No", "Not In Scope", IF('2-3. Assessment & Actions'!P21="Select…. ","Not Answered",IF('2-3. Assessment & Actions'!P21=1,'2-3. Assessment & Actions'!L21,(IF('2-3. Assessment & Actions'!P21=2,'2-3. Assessment & Actions'!L22,'2-3. Assessment & Actions'!L23))))) -> Not Answered
B12: =_xlfn.XLOOKUP(E12,'2-3. Assessment & Actions'!D:D,'2-3. Assessment & Actions'!B:B) -> S1: Sustainability awareness/training for staff | C12: =_xlfn.XLOOKUP(B12, '1. Scope & Goals'!B:B,'1. Scope & Goals'!C:C) -> Yes | D12: =_xlfn.LET(_xlpm.val,_xlfn.XLOOKUP(B12,'1. Scope & Goals'!B:B,'1. Scope & Goals'!D:D), IF(_xlpm.val="Select…. ","N/A",_xlpm.val)) -> N/A | E12: S1.1 | F12: =IF(C12="No", "Not In Scope", IF('2-3. Assessment & Actions'!P25="Select…. ","Not Answered",IF('2-3. Assessment & Actions'!P25>=1,"Passed","Failed"))) -> Not Answered | G12: =IF(D12="No", "Not In Scope", IF('2-3. Assessment & Actions'!P25="Select…. ","Not Answered",IF('2-3. Assessment & Actions'!P25>=2,"Passed","Failed"))) -> Not Answered | H12: =IF(C12="No", "Not In Scope", IF('2-3. Assessment & Actions'!P25="Select…. ","Not Answered",IF('2-3. Assessment & Actions'!P25>=3,"Passed","Failed"))) -> Not Answered | I12: =IF(D12="N/A", "No target set", IF('2-3. Assessment & Actions'!P25="Select…. ", "No results given", IF('2-3. Assessment & Actions'!P25>=D12, "Targets met","Targets not met"))) -> No target set | J12: =IF(C12="No", "Not In Scope", IF('2-3. Assessment & Actions'!P25="Select…. ","Not Answered",IF('2-3. Assessment & Actions'!P25=1,'2-3. Assessment & Actions'!L25,(IF('2-3. Assessment & Actions'!P25=2,'2-3. Assessment & Actions'!L26,'2-3. Assessment & Actions'!L27))))) -> Not Answered
B13: =_xlfn.XLOOKUP(E13,'2-3. Assessment & Actions'!D:D,'2-3. Assessment & Actions'!B:B) -> S2: Involvement of stakeholders in environmental planning | C13: =_xlfn.XLOOKUP(B13, '1. Scope & Goals'!B:B,'1. Scope & Goals'!C:C) -> Yes | D13: =_xlfn.LET(_xlpm.val,_xlfn.XLOOKUP(B13,'1. Scope & Goals'!B:B,'1. Scope & Goals'!D:D), IF(_xlpm.val="Select…. ","N/A",_xlpm.val)) -> N/A | E13: S2.1 | F13: =IF(C13="No", "Not In Scope", IF('2-3. Assessment & Actions'!P28="Select…. ","Not Answered",IF('2-3. Assessment & Actions'!P28>=1,"Passed","Failed"))) -> Not Answered | G13: =IF(C13="No", "Not In Scope", IF('2-3. Assessment & Actions'!P28="Select…. ","Not Answered",IF('2-3. Assessment & Actions'!P28>=2,"Passed","Failed"))) -> Not Answered | H13: =IF(C13="No", "Not In Scope", IF('2-3. Assessment & Actions'!P28="Select…. ","Not Answered",IF('2-3. Assessment & Actions'!P28>=3,"Passed","Failed"))) -> Not Answered | I13: =IF(D13="N/A", "No target set", IF('2-3. Assessment & Actions'!P28="Select…. ", "No results given", IF('2-3. Assessment & Actions'!P28>=D13, "Targets met","Targets not met"))) -> No target set | J13: =IF(C13="No", "Not In Scope", IF('2-3. Assessment & Actions'!P28="Select…. ","Not Answered",IF('2-3. Assessment & Actions'!P28=1,'2-3. Assessment & Actions'!L28,(IF('2-3. Assessment & Actions'!P28=2,'2-3. Assessment & Actions'!L29,'2-3. Assessment & Actions'!L30))))) -> Not Answered
B14: =_xlfn.XLOOKUP(E14,'2-3. Assessment & Actions'!D:D,'2-3. Assessment & Actions'!B:B) -> S3: Transparent communication of environmental performance | C14: =_xlfn.XLOOKUP(B14, '1. Scope & Goals'!B:B,'1. Scope & Goals'!C:C) -> Yes | D14: =_xlfn.LET(_xlpm.val,_xlfn.XLOOKUP(B14,'1. Scope & Goals'!B:B,'1. Scope & Goals'!D:D), IF(_xlpm.val="Select…. ","N/A",_xlpm.val)) -> N/A | E14: S3.1 | F14: =IF(C14="No", "Not In Scope", IF('2-3. Assessment & Actions'!P31="Select…. ","Not Answered",IF('2-3. Assessment & Actions'!P31>=1,"Passed","Failed"))) -> Not Answered | G14: =IF(C14="No", "Not In Scope", IF('2-3. Assessment & Actions'!P31="Select…. ","Not Answered",IF('2-3. Assessment & Actions'!P31>=2,"Passed","Failed"))) -> Not Answered | H14: =IF(C14="No", "Not In Scope", IF('2-3. Assessment & Actions'!P31="Select…. ","Not Answered",IF('2-3. Assessment & Actions'!P31>=3,"Passed","Failed"))) -> Not Answered | I14: =IF(D14="N/A", "No target set", IF('2-3. Assessment & Actions'!P31="Select…. ", "No results given", IF('2-3. Assessment & Actions'!P31>=D14, "Targets met","Targets not met"))) -> No target set | J14: =IF(C14="No", "Not In Scope", IF('2-3. Assessment & Actions'!P31="Select…. ","Not Answered",IF('2-3. Assessment & Actions'!P31=1,'2-3. Assessment & Actions'!L31,(IF('2-3. Assessment & Actions'!P31=2,'2-3. Assessment & Actions'!L32,'2-3. Assessment & Actions'!L33))))) -> Not Answered
B15: =_xlfn.XLOOKUP(E15,'2-3. Assessment & Actions'!D:D,'2-3. Assessment & Actions'!B:B) -> E1: Adoption of renewable energy sources | C15: =_xlfn.XLOOKUP(B15, '1. Scope & Goals'!B:B,'1. Scope & Goals'!C:C) -> Yes | D15: =_xlfn.LET(_xlpm.val,_xlfn.XLOOKUP(B15,'1. Scope & Goals'!B:B,'1. Scope & Goals'!D:D), IF(_xlpm.val="Select…. ","N/A",_xlpm.val)) -> N/A | E15: E1.1 | F15: =IF(C15="No", "Not In Scope", IF('2-3. Assessment & Actions'!P35="Select…. ","Not Answered",IF('2-3. Assessment & Actions'!P35>=1,"Passed","Failed"))) -> Not Answered | G15: =IF(C15="No", "Not In Scope", IF('2-3. Assessment & Actions'!P35="Select…. ","Not Answered",IF('2-3. Assessment & Actions'!P35>=2,"Passed","Failed"))) -> Not Answered | H15: =IF(C15="No", "Not In Scope", IF('2-3. Assessment & Actions'!P35="Select…. ","Not Answered",IF('2-3. Assessment & Actions'!P35>=3,"Passed","Failed"))) -> Not Answered | I15: =IF(D15="N/A", "No target set", IF('2-3. Assessment & Actions'!P35="Select…. ", "No results given", IF('2-3. Assessment & Actions'!P35>=D15, "Targets met","Targets not met"))) -> No target set | J15: =IF(C15="No", "Not In Scope", IF('2-3. Assessment & Actions'!P35="Select…. ","Not Answered",IF('2-3. Assessment & Actions'!P35=1,'2-3. Assessment & Actions'!L35,(IF('2-3. Assessment & Actions'!P35=2,'2-3. Assessment & Actions'!L36,'2-3. Assessment & Actions'!L37))))) -> Not Answered
B16: =_xlfn.XLOOKUP(E16,'2-3. Assessment & Actions'!D:D,'2-3. Assessment & Actions'!B:B) -> E2: AI-driven workload or energy optimisation | C16: =_xlfn.XLOOKUP(B16, '1. Scope & Goals'!B:B,'1. Scope & Goals'!C:C) -> Yes | D16: =_xlfn.LET(_xlpm.val,_xlfn.XLOOKUP(B16,'1. Scope & Goals'!B:B,'1. Scope & Goals'!D:D), IF(_xlpm.val="Select…. ","N/A",_xlpm.val)) -> N/A | E16: E2.1 | F16: =IF(C16="No", "Not In Scope", IF('2-3. Assessment & Actions'!P38="Select…. ","Not Answered",IF('2-3. Assessment & Actions'!P38>=1,"Passed","Failed"))) -> Not Answered | G16: =IF(C16="No", "Not In Scope", IF('2-3. Assessment & Actions'!P38="Select…. ","Not Answered",IF('2-3. Assessment & Actions'!P38>=2,"Passed","Failed"))) -> Not Answered | H16: =IF(C16="No", "Not In Scope", IF('2-3. Assessment & Actions'!P38="Select…. ","Not Answered",IF('2-3. Assessment & Actions'!P38>=3,"Passed","Failed"))) -> Not Answered | I16: =IF(D16="N/A", "No target set", IF('2-3. Assessment & Actions'!P38="Select…. ", "No results given", IF('2-3. Assessment & Actions'!P38>=D16, "Targets met","Targets not met"))) -> No target set | J16: =IF(C16="No", "Not In Scope", IF('2-3. Assessment & Actions'!P38="Select…. ","Not Answered",IF('2-3. Assessment & Actions'!P38=1,'2-3. Assessment & Actions'!L38,(IF('2-3. Assessment & Actions'!P38=2,'2-3. Assessment & Actions'!L39,'2-3. Assessment & Actions'!L40))))) -> Not Answered
B17: =_xlfn.XLOOKUP(E17,'2-3. Assessment & Actions'!D:D,'2-3. Assessment & Actions'!B:B) -> E3: Waste heat recovery or reuse strategies | C17: =_xlfn.XLOOKUP(B17, '1. Scope & Goals'!B:B,'1. Scope & Goals'!C:C) -> Yes | D17: =_xlfn.LET(_xlpm.val,_xlfn.XLOOKUP(B17,'1. Scope & Goals'!B:B,'1. Scope & Goals'!D:D), IF(_xlpm.val="Select…. ","N/A",_xlpm.val)) -> N/A | E17: E3.1 | F17: =IF(C17="No", "Not In Scope", IF('2-3. Assessment & Actions'!P41="Select…. ","Not Answered",IF('2-3. Assessment & Actions'!P41>=1,"Passed","Failed"))) -> Not Answered | G17: =IF(C17="No", "Not In Scope", IF('2-3. Assessment & Actions'!P41="Select…. ","Not Answered",IF('2-3. Assessment & Actions'!P41>=2,"Passed","Failed"))) -> Not Answered | H17: =IF(C17="No", "Not In Scope", IF('2-3. Assessment & Actions'!P41="Select…. ","Not Answered",IF('2-3. Assessment & Actions'!P41>=3,"Passed","Failed"))) -> Not Answered | I17: =IF(D17="N/A", "No target set", IF('2-3. Assessment & Actions'!P41="Select…. ", "No results given", IF('2-3. Assessment & Actions'!P41>=D17, "Targets met","Targets not met"))) -> No target set | J17: =IF(C17="No", "Not In Scope", IF('2-3. Assessment & Actions'!P41="Select…. ","Not Answered",IF('2-3. Assessment & Actions'!P41=1,'2-3. Assessment & Actions'!L41,(IF('2-3. Assessment & Actions'!P41=2,'2-3. Assessment & Actions'!L42,'2-3. Assessment & Actions'!L43))))) -> Not Answered
B18: =_xlfn.XLOOKUP(E18,'2-3. Assessment & Actions'!D:D,'2-3. Assessment & Actions'!B:B) -> E4: Power Usage Effectiveness (PUE) tracking and optimisation | C18: =_xlfn.XLOOKUP(B18, '1. Scope & Goals'!B:B,'1. Scope & Goals'!C:C) -> Yes | D18: =_xlfn.LET(_xlpm.val,_xlfn.XLOOKUP(B18,'1. Scope & Goals'!B:B,'1. Scope & Goals'!D:D), IF(_xlpm.val="Select…. ","N/A",_xlpm.val)) -> N/A | E18: E4.1 | F18: =IF(C18="No", "Not In Scope", IF('2-3. Assessment & Actions'!P44="Select…. ","Not Answered",IF('2-3. Assessment & Actions'!P44>=1,"Passed","Failed"))) -> Not Answered | G18: =IF(C18="No", "Not In Scope", IF('2-3. Assessment & Actions'!P44="Select…. ","Not Answered",IF('2-3. Assessment & Actions'!P44>=2,"Passed","Failed"))) -> Not Answered | H18: =IF(C18="No", "Not In Scope", IF('2-3. Assessment & Actions'!P44="Select…. ","Not Answered",IF('2-3. Assessment & Actions'!P44>=3,"Passed","Failed"))) -> Not Answered | I18: =IF(D18="N/A", "No target set", IF('2-3. Assessment & Actions'!P44="Select…. ", "No results given", IF('2-3. Assessment & Actions'!P44>=D18, "Targets met","Targets not met"))) -> No target set | J18: =IF(C18="No", "Not In Scope", IF('2-3. Assessment & Actions'!P44="Select…. ","Not Answered",IF('2-3. Assessment & Actions'!P44=1,'2-3. Assessment & Actions'!L44,(IF('2-3. Assessment & Actions'!P44=2,'2-3. Assessment & Actions'!L45,'2-3. Assessment & Actions'!L46))))) -> Not Answered
B19: =_xlfn.XLOOKUP(E19,'2-3. Assessment & Actions'!D:D,'2-3. Assessment & Actions'!B:B) -> E5: Carbon Use Effectiveness (CUE) tracking and reduction | C19: =_xlfn.XLOOKUP(B19, '1. Scope & Goals'!B:B,'1. Scope & Goals'!C:C) -> Yes | D19: =_xlfn.LET(_xlpm.val,_xlfn.XLOOKUP(B19,'1. Scope & Goals'!B:B,'1. Scope & Goals'!D:D), IF(_xlpm.val="Select…. ","N/A",_xlpm.val)) -> N/A | E19: E5.1 | F19: =IF(C19="No", "Not In Scope", IF('2-3. Assessment & Actions'!P47="Select…. ","Not Answered",IF('2-3. Assessment & Actions'!P47>=1,"Passed","Failed"))) -> Not Answered | G19: =IF(C19="No", "Not In Scope", IF('2-3. Assessment & Actions'!P47="Select…. ","Not Answered",IF('2-3. Assessment & Actions'!P47>=2,"Passed","Failed"))) -> Not Answered | H19: =IF(C19="No", "Not In Scope", IF('2-3. Assessment & Actions'!P47="Select…. ","Not Answered",IF('2-3. Assessment & Actions'!P47>=3,"Passed","Failed"))) -> Not Answered | I19: =IF(D19="N/A", "No target set", IF('2-3. Assessment & Actions'!P47="Select…. ", "No results given", IF('2-3. Assessment & Actions'!P47>=D19, "Targets met","Targets not met"))) -> No target set | J19: =IF(C19="No", "Not In Scope", IF('2-3. Assessment & Actions'!P47="Select…. ","Not Answered",IF('2-3. Assessment & Actions'!P47=1,'2-3. Assessment & Actions'!L47,(IF('2-3. Assessment & Actions'!P47=2,'2-3. Assessment & Actions'!L48,'2-3. Assessment & Actions'!L49))))) -> Not Answered
B20: =_xlfn.XLOOKUP(E20,'2-3. Assessment & Actions'!D:D,'2-3. Assessment & Actions'!B:B) -> E6: Flexible energy usage or smart grid responsiveness | C20: =_xlfn.XLOOKUP(B20, '1. Scope & Goals'!B:B,'1. Scope & Goals'!C:C) -> Yes | D20: =_xlfn.LET(_xlpm.val,_xlfn.XLOOKUP(B20,'1. Scope & Goals'!B:B,'1. Scope & Goals'!D:D), IF(_xlpm.val="Select…. ","N/A",_xlpm.val)) -> N/A | E20: E6.1 | F20: =IF(C20="No", "Not In Scope", IF('2-3. Assessment & Actions'!P50="Select…. ","Not Answered",IF('2-3. Assessment & Actions'!P50>=1,"Passed","Failed"))) -> Not Answered | G20: =IF(C20="No", "Not In Scope", IF('2-3. Assessment & Actions'!P50="Select…. ","Not Answered",IF('2-3. Assessment & Actions'!P50>=2,"Passed","Failed"))) -> Not Answered | H20: =IF(C20="No", "Not In Scope", IF('2-3. Assessment & Actions'!P50="Select…. ","Not Answered",IF('2-3. Assessment & Actions'!P50>=3,"Passed","Failed"))) -> Not Answered | I20: =IF(D20="N/A", "No target set", IF('2-3. Assessment & Actions'!P50="Select…. ", "No results given", IF('2-3. Assessment & Actions'!P50>=D20, "Targets met","Targets not met"))) -> No target set | J20: =IF(C20="No", "Not In Scope", IF('2-3. Assessment & Actions'!P50="Select…. ","Not Answered",IF('2-3. Assessment & Actions'!P50=1,'2-3. Assessment & Actions'!L50,(IF('2-3. Assessment & Actions'!P50=2,'2-3. Assessment & Actions'!L51,'2-3. Assessment & Actions'!L52))))) -> Not Answered
B21: =_xlfn.XLOOKUP(E21,'2-3. Assessment & Actions'!D:D,'2-3. Assessment & Actions'!B:B) -> M1: Measurement of environmental KPIs (GHG, energy, water, waste) | C21: =_xlfn.XLOOKUP(B21, '1. Scope & Goals'!B:B,'1. Scope & Goals'!C:C) -> Yes | D21: =_xlfn.LET(_xlpm.val,_xlfn.XLOOKUP(B21,'1. Scope & Goals'!B:B,'1. Scope & Goals'!D:D), IF(_xlpm.val="Select…. ","N/A",_xlpm.val)) -> N/A | E21: M1.1 | F21: =IF(C21="No", "Not In Scope", IF('2-3. Assessment & Actions'!P54="Select…. ","Not Answered",IF('2-3. Assessment & Actions'!P54>=1,"Passed","Failed"))) -> Not Answered | G21: =IF(C21="No", "Not In Scope", IF('2-3. Assessment & Actions'!P54="Select…. ","Not Answered",IF('2-3. Assessment & Actions'!P54>=2,"Passed","Failed"))) -> Not Answered | H21: =IF(C21="No", "Not In Scope", IF('2-3. Assessment & Actions'!P54="Select…. ","Not Answered",IF('2-3. Assessment & Actions'!P54>=3,"Passed","Failed"))) -> Not Answered | I21: =IF(D21="N/A", "No target set", IF('2-3. Assessment & Actions'!P54="Select…. ", "No results given", IF('2-3. Assessment & Actions'!P54>=D21, "Targets met","Targets not met"))) -> No target set | J21: =IF(C21="No", "Not In Scope", IF('2-3. Assessment & Actions'!P54="Select…. ","Not Answered",IF('2-3. Assessment & Actions'!P54=1,'2-3. Assessment & Actions'!L54,(IF('2-3. Assessment & Actions'!P54=2,'2-3. Assessment & Actions'!L55,'2-3. Assessment & Actions'!L56))))) -> Not Answered
B22: =_xlfn.XLOOKUP(E22,'2-3. Assessment & Actions'!D:D,'2-3. Assessment & Actions'!B:B) -> M2: Use of environmental metrics in planning and reporting | C22: =_xlfn.XLOOKUP(B22, '1. Scope & Goals'!B:B,'1. Scope & Goals'!C:C) -> Yes | D22: =_xlfn.LET(_xlpm.val,_xlfn.XLOOKUP(B22,'1. Scope & Goals'!B:B,'1. Scope & Goals'!D:D), IF(_xlpm.val="Select…. ","N/A",_xlpm.val)) -> N/A | E22: M2.1 | F22: =IF(C22="No", "Not In Scope", IF('2-3. Assessment & Actions'!P57="Select…. ","Not Answered",IF('2-3. Assessment & Actions'!P57>=1,"Passed","Failed"))) -> Not Answered | G22: =IF(C22="No", "Not In Scope", IF('2-3. Assessment & Actions'!P57="Select…. ","Not Answered",IF('2-3. Assessment & Actions'!P57>=2,"Passed","Failed"))) -> Not Answered | H22: =IF(C22="No", "Not In Scope", IF('2-3. Assessment & Actions'!P57="Select…. ","Not Answered",IF('2-3. Assessment & Actions'!P57>=3,"Passed","Failed"))) -> Not Answered | I22: =IF(D22="N/A", "No target set", IF('2-3. Assessment & Actions'!P57="Select…. ", "No results given", IF('2-3. Assessment & Actions'!P57>=D22, "Targets met","Targets not met"))) -> No target set | J22: =IF(C22="No", "Not In Scope", IF('2-3. Assessment & Actions'!P57="Select…. ","Not Answered",IF('2-3. Assessment & Actions'!P57=1,'2-3. Assessment & Actions'!L57,(IF('2-3. Assessment & Actions'!P57=2,'2-3. Assessment & Actions'!L58,'2-3. Assessment & Actions'!L59))))) -> Not Answered
B23: =_xlfn.XLOOKUP(E23,'2-3. Assessment & Actions'!D:D,'2-3. Assessment & Actions'!B:B) -> M3: Lifecycle-based environmental impact assessment (based on LCA methodology) | C23: =_xlfn.XLOOKUP(B23, '1. Scope & Goals'!B:B,'1. Scope & Goals'!C:C) -> Yes | D23: =_xlfn.LET(_xlpm.val,_xlfn.XLOOKUP(B23,'1. Scope & Goals'!B:B,'1. Scope & Goals'!D:D), IF(_xlpm.val="Select…. ","N/A",_xlpm.val)) -> N/A | E23: M3.1 | F23: =IF(C23="No", "Not In Scope", IF('2-3. Assessment & Actions'!P60="Select…. ","Not Answered",IF('2-3. Assessment & Actions'!P60>=1,"Passed","Failed"))) -> Not Answered | G23: =IF(C23="No", "Not In Scope", IF('2-3. Assessment & Actions'!P60="Select…. ","Not Answered",IF('2-3. Assessment & Actions'!P60>=2,"Passed","Failed"))) -> Not Answered | H23: =IF(C23="No", "Not In Scope", IF('2-3. Assessment & Actions'!P60="Select…. ","Not Answered",IF('2-3. Assessment & Actions'!P60>=3,"Passed","Failed"))) -> Not Answered | I23: =IF(D23="N/A", "No target set", IF('2-3. Assessment & Actions'!P60="Select…. ", "No results given", IF('2-3. Assessment & Actions'!P60>=D23, "Targets met","Targets not met"))) -> No target set | J23: =IF(C23="No", "Not In Scope", IF('2-3. Assessment & Actions'!P60="Select…. ","Not Answered",IF('2-3. Assessment & Actions'!P60=1,'2-3. Assessment & Actions'!L60,(IF('2-3. Assessment & Actions'!P60=2,'2-3. Assessment & Actions'!L61,'2-3. Assessment & Actions'!L62))))) -> Not Answered
B24: =_xlfn.XLOOKUP(E24,'2-3. Assessment & Actions'!D:D,'2-3. Assessment & Actions'!B:B) -> M4: Use of WUE (Water Usage Effectiveness) or similar water metrics | C24: =_xlfn.XLOOKUP(B24, '1. Scope & Goals'!B:B,'1. Scope & Goals'!C:C) -> Yes | D24: =_xlfn.LET(_xlpm.val,_xlfn.XLOOKUP(B24,'1. Scope & Goals'!B:B,'1. Scope & Goals'!D:D), IF(_xlpm.val="Select…. ","N/A",_xlpm.val)) -> N/A | E24: M4.1 | F24: =IF(C24="No", "Not In Scope", IF('2-3. Assessment & Actions'!P63="Select…. ","Not Answered",IF('2-3. Assessment & Actions'!P63>=1,"Passed","Failed"))) -> Not Answered | G24: =IF(C24="No", "Not In Scope", IF('2-3. Assessment & Actions'!P63="Select…. ","Not Answered",IF('2-3. Assessment & Actions'!P63>=2,"Passed","Failed"))) -> Not Answered | H24: =IF(C24="No", "Not In Scope", IF('2-3. Assessment & Actions'!P63="Select…. ","Not Answered",IF('2-3. Assessment & Actions'!P63>=3,"Passed","Failed"))) -> Not Answered | I24: =IF(D24="N/A", "No target set", IF('2-3. Assessment & Actions'!P63="Select…. ", "No results given", IF('2-3. Assessment & Actions'!P63>=D24, "Targets met","Targets not met"))) -> No target set | J24: =IF(C24="No", "Not In Scope", IF('2-3. Assessment & Actions'!P63="Select…. ","Not Answered",IF('2-3. Assessment & Actions'!P63=1,'2-3. Assessment & Actions'!L64,(IF('2-3. Assessment & Actions'!P63=2,'2-3. Assessment & Actions'!L64,'2-3. Assessment & Actions'!L65))))) -> Not Answered
B25: =_xlfn.XLOOKUP(E25,'2-3. Assessment & Actions'!D:D,'2-3. Assessment & Actions'!B:B) -> M5: Implementation of monitoring tools/platforms | C25: =_xlfn.XLOOKUP(B25, '1. Scope & Goals'!B:B,'1. Scope & Goals'!C:C) -> Yes | D25: =_xlfn.LET(_xlpm.val,_xlfn.XLOOKUP(B25,'1. Scope & Goals'!B:B,'1. Scope & Goals'!D:D), IF(_xlpm.val="Select…. ","N/A",_xlpm.val)) -> N/A | E25: M5.1 | F25: =IF(C25="No", "Not In Scope", IF('2-3. Assessment & Actions'!P66="Select…. ","Not Answered",IF('2-3. Assessment & Actions'!P66>=1,"Passed","Failed"))) -> Not Answered | G25: =IF(D25="No", "Not In Scope", IF('2-3. Assessment & Actions'!P66="Select…. ","Not Answered",IF('2-3. Assessment & Actions'!P66>=2,"Passed","Failed"))) -> Not Answered | H25: =IF(C25="No", "Not In Scope", IF('2-3. Assessment & Actions'!P66="Select…. ","Not Answered",IF('2-3. Assessment & Actions'!P66>=3,"Passed","Failed"))) -> Not Answered | I25: =IF(D25="N/A", "No target set", IF('2-3. Assessment & Actions'!P66="Select…. ", "No results given", IF('2-3. Assessment & Actions'!P66>=D25, "Targets met","Targets not met"))) -> No target set | J25: =IF(C25="No", "Not In Scope", IF('2-3. Assessment & Actions'!P66="Select…. ","Not Answered",IF('2-3. Assessment & Actions'!P66=1,'2-3. Assessment & Actions'!L66,(IF('2-3. Assessment & Actions'!P66=2,'2-3. Assessment & Actions'!L67,'2-3. Assessment & Actions'!L68))))) -> Not Answered
B26: =_xlfn.XLOOKUP(E26,'2-3. Assessment & Actions'!D:D,'2-3. Assessment & Actions'!B:B) -> P1: Reduction of operational waste (incl. e-waste) | C26: =_xlfn.XLOOKUP(B26, '1. Scope & Goals'!B:B,'1. Scope & Goals'!C:C) -> Yes | D26: =_xlfn.LET(_xlpm.val,_xlfn.XLOOKUP(B26,'1. Scope & Goals'!B:B,'1. Scope & Goals'!D:D), IF(_xlpm.val="Select…. ","N/A",_xlpm.val)) -> N/A | E26: P1.1 | F26: =IF(C26="No", "Not In Scope", IF('2-3. Assessment & Actions'!P70="Select…. ","Not Answered",IF('2-3. Assessment & Actions'!P70>=1,"Passed","Failed"))) -> Not Answered | G26: =IF(C26="No", "Not In Scope", IF('2-3. Assessment & Actions'!P70="Select…. ","Not Answered",IF('2-3. Assessment & Actions'!P70>=2,"Passed","Failed"))) -> Not Answered | H26: =IF(C26="No", "Not In Scope", IF('2-3. Assessment & Actions'!P70="Select…. ","Not Answered",IF('2-3. Assessment & Actions'!P70>=3,"Passed","Failed"))) -> Not Answered | I26: =IF(D26="N/A", "No target set", IF('2-3. Assessment & Actions'!P70="Select…. ", "No results given", IF('2-3. Assessment & Actions'!P70>=D26, "Targets met","Targets not met"))) -> No target set | J26: =IF(C26="No", "Not In Scope", IF('2-3. Assessment & Actions'!P70="Select…. ","Not Answered",IF('2-3. Assessment & Actions'!P70=1,'2-3. Assessment & Actions'!L70,(IF('2-3. Assessment & Actions'!P70=2,'2-3. Assessment & Actions'!L71,'2-3. Assessment & Actions'!L72))))) -> Not Answered
